Workbook

Sheet Levantamento
A1: Código IBGE | B1: Região | C1: UF | D1: Município | E1: RIDE RM AU - IBGE 2024 | F1: RMs ENMU | G1: Área de Estudo ENMU | H1: Mapa do Turismo Brasileiro 2022 | I1: Mapa do Turismo Brasileiro 2024 | J1: Tipologia PNDU | K1: População - Censo 2010 | L1: Faixa Populacional - Censo 2010 | M1: População - Censo 2022 | N1: Faixa Populacional - Censo 2022 | O1: Estimativa populacional 2025 | P1: Faixa populacional - 2025 | Q1: Ofício | R1: Respondeu ao levantamento | S1: Possui Plano de Mobilidade Urbana | T1: Ano de elaboração | U1: Aprovado em lei ou ato normativo | V1: Instrumento Legal | W1: Nº da Lei | X1: Data da Lei | Y1: Link | Z1: Arquivo | AA1: Sistemas de Informação | AB1: Elaborando plano | AC1: Previsão de conclusão | AD1: Repondido por qual instrumento | AE1: Data da resposta | AF1: Fonte da Resposta | AG1: Obrigados Estimativa 2025 | AH1: Obrigados Censo 2022 - antigo | AI1: Obrigados Censo 2022 - atualizado
A2: 3550308 | B2: SE | C2: SP | D2: São Paulo | E2: RM de São Paulo (SP) | F2: Sim | G2: Sim | H2: A | I2: #N/A | J2: CD 1A | K2: 11253503 | L2: Mais de 1 milhão | M2: 11451999 | N2: Mais de 1 milhão | O2: 11904961 | P2: Mais de 1 milhão | Q2: Sim | R2: Sim | S2: Sim | T2: 2016 | U2: Sim | V2: Decreto Municipal | W2: 56.834/2016 | X2: 42424 | Y2: http://www.prefeitura.sp.gov.br/cidade/secretarias/transportes/planmob/ | Z2: \\londrina\SNTMU$\a. DEPARTAMENTOS\i. DEPLAN\2.CGARG\SIMU\Levantamento Planos de Mobilidade 2019\Planos Municipais - exemplos\SUDESTE\São Paulo\São Paulo_SP | AA2: https://www.prefeitura.sp.gov.br/cidade/secretarias/mobilidade/institucional/sptrans/acesso_a_informacao/index.php?p=295718; https://www.sptrans.com.br/terminais-corredores-e-pontos-de-parada; https://www.sptrans.com.br/desenvolvedores/ | AB2: Nao | AD2: Ofício nº 10/2016 | AE2: 42499 | AG2: Sim | AH2: Sim | AI2: Sim
A3: 3304557 | B3: SE | C3: RJ | D3: Rio de Janeiro | E3: RM do Rio de Janeiro (RJ) | F3: Sim | G3: Sim | H3: A | I3: A | J3: CD 1A | K3: 6320446 | L3: Mais de 1 milhão | M3: 6211223 | N3: Mais de 1 milhão | O3: 6730729 | P3: Mais de 1 milhão | Q3: Sim | R3: Sim | S3: Sim | T3: 2019 | U3: Sim | V3: Decreto Municipal | W3: 4.571/2019 | X3: 43558 | Y3: www.rio.rj.gov.br/web/pmus | Z3: \\Londrina\sntmu$\a. DEPARTAMENTOS\i. DEPLAN\2.CGARG\SIMU\Levantamento Planos de Mobilidade 2019\Planos Municipais - exemplos\SUDESTE\Rio de Janeiro\Rio de Janeiro_RJ | AA3: https://www.data.rio/search?groupIds=cbe84df2333a463b9d4e20aca5177936&sort=-modified | AB3: Nao | AD3: Ofício nº 21/2019 | AE3: 43570 | AF3: Pesquisa PlanMob 2019 | AG3: Sim | AH3: Sim | AI3: Sim
A4: 5300108 | B4: CO | C4: DF | D4: Brasília | E4: RIDE do Distrito Federal e Entorno | F4: Sim | G4: Sim | H4: A | I4: A | J4: CD 1A | K4: 2570160 | L4: Mais de 1 milhão | M4: 2817381 | N4: Mais de 1 milhão | O4: 2996899 | P4: Mais de 1 milhão | Q4: Sim | R4: Sim | S4: Sim | T4: 2011 | U4: Sim | V4: Lei Distrital | W4: 4.566/2011 | X4: 40667 | Y4: http://www.semob.df.gov.br/pdtu/ | Z4: \\Londrina\sntmu$\a. DEPARTAMENTOS\i. DEPLAN\2.CGARG\SIMU\Levantamento Planos de Mobilidade 2019\Planos Municipais - exemplos\CENTRO-OESTE\Brasília_DF | AA4: https://geoserver.semob.df.gov.br/geoserver/web/wicket/bookmarkable/org.geoserver.web.demo.MapPreviewPage?0&filter=false http://dados.df.gov.br/organization/d264c504-23b4-40fd-afb2-1ec81912f943?groups=mobilidade | AB4: Nao | AD4: Pemob/2019 | AG4: Sim | AH4: Sim | AI4: Sim
A5: 2304400 | B5: NE | C5: CE | D5: Fortaleza | E5: RM de Fortaleza (CE) | F5: Sim | G5: Sim | H5: A | I5: A | J5: CD 1A | K5: 2452185 | L5: Mais de 1 milhão | M5: 2428708 | N5: Mais de 1 milhão | O5: 2578483 | P5: Mais de 1 milhão | Q5: Sim | R5: Sim | S5: Sim | T5: 2023 | U5: Sim | V5: Lei Municipal | W5: 11390/2023 | X5: 45187 | Y5: https://sapl.fortaleza.ce.leg.br/norma/13698?display= https://fortaleza2040.fortaleza.ce.gov.br/site/assets/files/publications/fortaleza2040_plano_de_mobilidade_urbana_17-08-2015.pdf | Z5: \\Londrina\sntmu$\a. DEPARTAMENTOS\i. DEPLAN\2.CGARG\SIMU\Levantamento Planos de Mobilidade 2019\Planos Municipais - exemplos\NORDESTE\Fortaleza_CE | AA5: https://dados.fortaleza.ce.gov.br/dataset/?groups=transporte | AB5: Nao | AD5: Pemob 2025 | AE5: 45894 | AF5: Victor Macêdo Lacerda | AG5: Sim | AH5: Sim | AI5: Sim
A6: 2927408 | B6: NE | C6: BA | D6: Salvador | E6: RM de Salvador (BA) | F6: Sim | G6: Sim | H6: A | I6: A | J6: CD 1A | K6: 2675656 | L6: Mais de 1 milhão | M6: 2417678 | N6: Mais de 1 milhão | O6: 2564204 | P6: Mais de 1 milhão | Q6: Sim | R6: Sim | S6: Sim | T6: 2018 | U6: Sim | V6: Lei Municipal | W6: 9.374/2018 | X6: 43286 | Y6: http://www.planmob.salvador.ba.gov.br/ | Z6: \\Londrina\sntmu$\a. DEPARTAMENTOS\i. DEPLAN\2.CGARG\SIMU\Levantamento Planos de Mobilidade 2019\Planos Municipais - exemplos\NORDESTE\Salvador_BA | AA6: https://dados.salvador.ba.gov.br/search?tags=transito | AB6: Nao | AD6: Ofício nº 154/2017 | AE6: 43291 | AG6: Sim | AH6: Sim | AI6: Sim
A7: 3106200 | B7: SE | C7: MG | D7: Belo Horizonte | E7: RM de Belo Horizonte (MG) | F7: Sim | G7: Sim | H7: A | I7: A | J7: CD 1A | K7: 2375151 | L7: Mais de 1 milhão | M7: 2315560 | N7: Mais de 1 milhão | O7: 2415872 | P7: Mais de 1 milhão | Q7: Sim | R7: Sim | S7: Sim | T7: 2019 | U7: Sim | V7: Lei Municipal (Plano Diretor) | W7: 11.181/2019 | X7: 43685 | Y7: https://prefeitura.pbh.gov.br/politica-urbana/planejamento-urbano/plano-diretor/proposta | Z7: L:\a. DEPARTAMENTOS\i. DEPLAN\2.CGARG\SIMU\Levantamento Planos de Mobilidade 2019\Planos Municipais - exemplos\SUDESTE\Minas Gerais\Belo Horizonte_MG | AA7: https://dados.pbh.gov.br/organization/bhtrans | AB7: Nao | AD7: Pemob 2019 | AE7: 43840 | AG7: Sim | AH7: Sim | AI7: Sim
A8: 1302603 | B8: N | C8: AM | D8: Manaus | E8: RM de Manaus (AM) | F8: Sim | G8: Sim | H8: A | I8: A | J8: CD 1C | K8: 1802014 | L8: Mais de 1 milhão | M8: 2063689 | N8: Mais de 1 milhão | O8: 2303732 | P8: Mais de 1 milhão | Q8: Sim | R8: Sim | S8: Sim | T8: 2015 | U8: Sim | V8: Lei Complementar | W8: 2.075/2015 | X8: 42367 | Y8: http://transporte.manaus.am.gov.br/planmob/ | Z8: L:\a. DEPARTAMENTOS\i. DEPLAN\2.CGARG\SIMU\Levantamento Planos de Mobilidade 2019\Planos Municipais - exemplos\NORTE\Manaus_AM | AB8: Nao | AD8: Ofício nº 01/2016 Pemob 2024 | AE8: 42398 | AG8: Sim | AH8: Sim | AI8: Sim
A9: 4106902 | B9: S | C9: PR | D9: Curitiba | E9: RM de Curitiba (PR) | F9: Sim | G9: Sim | H9: A | I9: A | J9: CD 1A | K9: 1751907 | L9: Mais de 1 milhão | M9: 1773718 | N9: Mais de 1 milhão | O9: 1830795 | P9: Mais de 1 milhão | Q9: Sim | R9: Sim | S9: Sim | T9: 2022 | U9: Sim | V9: Decreto Municipal | W9: 485/2023 | X9: 45013 | Y9: https://ippuc.org.br/mostrarpagina.php?pagina=312&idioma=1&ampliar=não https://ippuc.org.br/storage/uploads/0a2076cd-5284-4183-8aed-9c12c0aa617b/PS-Mobilidade-VOL-1.pdf | Z9: L:\a. DEPARTAMENTOS\i. DEPLAN\2.CGARG\SIMU\Levantamento Planos de Mobilidade 2019\Planos Municipais - exemplos\SUL\Paraná\Curitiba_PR | AB9: Nao | AD9: Pemob 2024 | AF9: Pemob 2024 | AG9: Sim | AH9: Sim | AI9: Sim
A10: 2611606 | B10: NE | C10: PE | D10: Recife | E10: RM de Recife (PE) | F10: Sim | G10: Sim | H10: A | I10: A | J10: CD 1A | K10: 1537704 | L10: Mais de 1 milhão | M10: 1488920 | N10: Mais de 1 milhão | O10: 1588376 | P10: Mais de 1 milhão | Q10: Sim | R10: Sim | S10: Sim | T10: 2021 | U10: Sim | V10: Lei Municipal | W10: 18887/2021 | X10: 44559 | Z10: L:\a. DEPARTAMENTOS\i. DEPLAN\2.CGARG\SIMU\Levantamento Planos de Mobilidade 2019\Planos Municipais - exemplos\NORDESTE\Recife_PE | AA10: http://dados.recife.pe.gov.br/nl/dataset?tags=transporte https://www.granderecife.pe.gov.br/transporte/dados-e-estatisticas/passageiros/ | AB10: Nao | AD10: Email | AE10: 44770 | AF10: cttupresidencia@recife.pe.gov.br | AG10: Sim | AH10: Sim | AI10: Sim
A11: 5208707 | B11: CO | C11: GO | D11: Goiânia | E11: RM de Goiânia (GO) | F11: Sim | G11: Sim | H11: A | I11: A | J11: CD 1A | K11: 1302001 | L11: Mais de 1 milhão | M11: 1437366 | N11: Mais de 1 milhão | O11: 1503256 | P11: Mais de 1 milhão | Q11: Sim | R11: Sim | S11: Sim | T11: 2024 | U11: Sim | V11: Decreto Municipal | W11: 1350/2024 | X11: 45394 | Y11: https://www.goiania.go.gov.br/html/gabinete_civil/sileg/dados/legis/2024/dc_20240412_000001350.html | AB11: Nao | AD11: Pemob 2024 | AE11: 45478 | AG11: Sim | AH11: Sim | AI11: Sim
A12: 1501402 | B12: N | C12: PA | D12: Belém | E12: RM de Belém (PA) | F12: Sim | G12: Sim | H12: A | I12: A | J12: CD 1A | K12: 1393399 | L12: Mais de 1 milhão | M12: 1303403 | N12: Mais de 1 milhão | O12: 1397315 | P12: Mais de 1 milhão | Q12: Sim | R12: Sim | S12: Sim | T12: 2016 | U12: Sim | V12: Decreto Municipal | W12: 86.545/2016 | X12: 42626 | Y12: http://www.belem.pa.gov.br/diarioom/baixarDiario?idd=8117 | Z12: L:\a. DEPARTAMENTOS\i. DEPLAN\2.CGARG\SIMU\Levantamento Planos de Mobilidade 2019\Planos Municipais - exemplos\NORTE\Belém_PA | AB12: Nao | AG12: Sim | AH12: Sim | AI12: Sim
A13: 4314902 | B13: S | C13: RS | D13: Porto Alegre | E13: RM de Porto Alegre (RS) | F13: Sim | G13: Sim | H13: A | I13: A | J13: CD 1A | K13: 1409351 | L13: Mais de 1 milhão | M13: 1332833 | N13: Mais de 1 milhão | O13: 1388794 | P13: Mais de 1 milhão | Q13: Sim | R13: Sim | S13: Sim | T13: 2022 | U13: Sim | V13: Lei Complementar | W13: 951/2022 | X13: 44790 | Y13: https://prefeitura.poa.br/smim/projetos/plano-de-mobilidade-urbana | Z13: L:\a. DEPARTAMENTOS\i. DEPLAN\2.CGARG\SIMU\Levantamento Planos de Mobilidade 2019\Planos Municipais - exemplos\SUL\Rio Grande do Sul\Porto Alegre_RS | AA13: https://dadosabertos.poa.br/group/mobilidade | AB13: Nao | AD13: E-mail | AE13: 45645 | AF13: joaquim@portoalegre.rs.gov.br | AG13: Sim | AH13: Sim | AI13: Sim
A14: 3518800 | B14: SE | C14: SP | D14: Guarulhos | E14: RM de São Paulo (SP) | F14: Sim | G14: Sim | H14: B | I14: B | J14: CD 1A | K14: 1221979 | L14: Mais de 1 milhão | M14: 1291771 | N14: Mais de 1 milhão | O14: 1349100 | P14: Mais de 1 milhão | Q14: Sim | R14: Sim | S14: Sim | T14: 2019 | U14: Sim | V14: Decreto Municipal | W14: 35931/2019 | X14: 43615 | Y14: https://www.guarulhos.sp.gov.br/plano-de-mobilidade-urbana-de-guarulhos | Z14: L:\a. DEPARTAMENTOS\i. DEPLAN\2.CGARG\SIMU\Levantamento Planos de Mobilidade\Planos Municipais - exemplos\SUDESTE\São Paulo\Guarulhos | AB14: Nao | AD14: Pemob/2019 | AG14: Sim | AH14: Sim | AI14: Sim
A15: 3509502 | B15: SE | C15: SP | D15: Campinas | E15: RM de Campinas (SP) | F15: Sim | G15: Sim | H15: A | I15: A | J15: CD 1A | K15: 1080113 | L15: Mais de 1 milhão | M15: 1139047 | N15: Mais de 1 milhão | O15: 1187974 | P15: Mais de 1 milhão | Q15: Sim | R15: Sim | S15: Sim | T15: 2019 | U15: Sim | V15: Decreto Municipal | W15: 20.571/2019 | X15: 43782 | Y15: https://bibliotecajuridica.campinas.sp.gov.br/index/visualizaroriginal/id/134989 | Z15: \\londrina\SNTMU$\a. DEPARTAMENTOS\i. DEPLAN\2.CGARG\SIMU\Levantamento Planos de Mobilidade 2019\Planos Municipais - exemplos\SUDESTE\São Paulo\Campinas_SP | AB15: Nao | AD15: Pemob/2019 | AG15: Sim | AH15: Sim | AI15: Sim
A16: 2111300 | B16: NE | C16: MA | D16: São Luís | E16: RM da Grande São Luís (MA) | F16: Sim | G16: Sim | H16: A | I16: A | J16: CD 1A | K16: 1014837 | L16: Mais de 1 milhão | M16: 1037775 | N16: Mais de 1 milhão | O16: 1089215 | P16: Mais de 1 milhão | Q16: Sim | R16: Sim | S16: Sim | T16: 2017 | U16: Sim | V16: Lei Municipal | W16: 6.292/2017 | X16: 43097 | Z16: L:\a. DEPARTAMENTOS\i. DEPLAN\2.CGARG\SIMU\Levantamento Planos de Mobilidade 2019\Planos Municipais - exemplos\NORDESTE\São Luís_MA | AB16: Nao | AD16: Ofício nº 21/2019 | AE16: 43549 | AF16: Pesquisa PlanMob 2019 | AG16: Sim | AH16: Sim | AI16: Sim
A17: 2704302 | B17: NE | C17: AL | D17: Maceió | E17: RM de Maceió (AL) | F17: Sim | G17: Sim | H17: A | I17: #N/A | J17: CD 1A | K17: 932748 | L17: De 500 mil a 1 milhão | M17: 957916 | N17: De 500 mil a 1 milhão | O17: 994952 | P17: De 500 mil a 1 milhão | Q17: Sim | R17: Sim | S17: Nao | U17: Nao possui plano | V17: Nao possui plano | X17: Nao possui plano | AB17: Sim | AC17: Sem previsao | AD17: Email | AE17: 44839 | AF17: chefiadegabinetesmtt@gmail.com | AG17: Sim | AH17: Sim | AI17: Sim
A18: 5002704 | B18: CO | C18: MS | D18: Campo Grande | E18: #N/A | F18: Não | G18: Nao | H18: A | I18: A | J18: CD 1C | K18: 786797 | L18: De 500 mil a 1 milhão | M18: 898100 | N18: De 500 mil a 1 milhão | O18: 962883 | P18: De 500 mil a 1 milhão | Q18: Sim | R18: Sim | S18: Sim | T18: 2024 | U18: Sim | V18: Lei Municipal | W18: 7282/2024 | X18: 45488 | Y18: http://www.pmcg.ms.gov.br/egov/downloadFile.php?id=11400&fileField=arquivo_dow&table=downloads&key=id_dow&sigla_sec=planurb https://www.campogrande.ms.gov.br/planurb/consulte-2/ | Z18: \\Londrina\sntmu$\a. DEPARTAMENTOS\i. DEPLAN\2.CGARG\SIMU\Levantamento Planos de Mobilidade 2019\Planos Municipais - exemplos\CENTRO-OESTE\Campo Grande_MS | AB18: Nao | AD18: Pemob 2024 | AE18: 45499 | AG18: Sim | AH18: Sim | AI18: Sim
A19: 3304904 | B19: SE | C19: RJ | D19: São Gonçalo | E19: RM do Rio de Janeiro (RJ) | F19: Sim | G19: Sim | H19: C | I19: #N/A | J19: CD 1A | K19: 999728 | L19: De 500 mil a 1 milhão | M19: 896744 | N19: De 500 mil a 1 milhão | O19: 960196 | P19: De 500 mil a 1 milhão | Q19: Sim | R19: Sim | S19: Sim | T19: 2024 | U19: Sim | V19: Lei Municipal | W19: 1529/2024 | X19: 45401 | AB19: Nao | AD19: Email | AE19: 45912 | AF19: apolotardin@gmail.com | AG19: Sim | AH19: Sim | AI19: Sim
A20: 2211001 | B20: NE | C20: PI | D20: Teresina | E20: RIDE da Grande Teresina (PI/MA) | F20: Sim | G20: Sim | H20: A | I20: A | J20: CD 1A | K20: 814230 | L20: De 500 mil a 1 milhão | M20: 866300 | N20: De 500 mil a 1 milhão | O20: 905692 | P20: De 500 mil a 1 milhão | Q20: Sim | R20: Sim | S20: Sim | T20: 2022 | U20: Nao | V20: Nao aprovado em lei | X20: Nao aprovado em lei | Y20: http://www.teresina.pi.gov.br/sistemas/portalpmt/admin/upload/documentos/f77f8cb7ca.pdf www.semplam.teresina.pi.gov.br/plano-diretor-de-transporte-e-mobilidade-urbana-de-teresin https://drive.google.com/file/d/1qNII-txnol3hdKZfA75c1Cs1G2fZydMe/view | Z20: \\Londrina\sntmu$\a. DEPARTAMENTOS\i. DEPLAN\2.CGARG\SIMU\Levantamento Planos de Mobilidade 2019\Planos Municipais - exemplos\NORDESTE\Teresina_PI | AB20: Nao | AD20: Ofício Nº 102/2024 - GABS-STRANS | AE20: 45309 | AF20: strans.gabinete@gmail.com | AG20: Sim | AH20: Sim | AI20: Sim
A21: 2507507 | B21: NE | C21: PB | D21: João Pessoa | E21: RM de João Pessoa (PB) | F21: Sim | G21: Sim | H21: A | I21: A | J21: CD 1A | K21: 723515 | L21: De 500 mil a 1 milhão | M21: 833932 | N21: De 500 mil a 1 milhão | O21: 897633 | P21: De 500 mil a 1 milhão | Q21: Sim | R21: Sim | S21: Sim | T21: 2022 | U21: Sim | V21: Lei Municipal | W21: 14515/2022 | X21: 44706 | Y21: https://www.youtube.com/watch?v=FrB6X2hZTDg&feature=youtu.be www.planmob.joaopessoa.pb.gov.br | AB21: Nao | AD21: E-mail | AE21: 45649 | AF21: gabscaprobertorodrigues@gmail.com | AG21: Sim | AH21: Sim | AI21: Sim
A22: 3301702 | B22: SE | C22: RJ | D22: Duque de Caxias | E22: RM do Rio de Janeiro (RJ) | F22: Sim | G22: Sim | H22: B | I22: B | J22: CD 1A | K22: 855048 | L22: De 500 mil a 1 milhão | M22: 808161 | N22: De 500 mil a 1 milhão | O22: 866225 | P22: De 500 mil a 1 milhão | Q22: Sim | R22: Nao | S22: Nao respondeu | U22: Nao respondeu | V22: Nao respondeu | X22: Nao respondeu | AB22: Nao respondeu | AG22: Sim | AH22: Sim | AI22: Sim
A23: 3303500 | B23: SE | C23: RJ | D23: Nova Iguaçu | E23: RM do Rio de Janeiro (RJ) | F23: Sim | G23: Sim | H23: C | I23: C | J23: CD 1A | K23: 796257 | L23: De 500 mil a 1 milhão | M23: 785867 | N23: De 500 mil a 1 milhão | O23: 843220 | P23: De 500 mil a 1 milhão | Q23: Sim | R23: Nao | S23: Nao respondeu | U23: Nao respondeu | V23: Nao respondeu | X23: Nao respondeu | AB23: Nao respondeu | AG23: Sim | AH23: Sim | AI23: Sim
A24: 3548708 | B24: SE | C24: SP | D24: São Bernardo do Campo | E24: RM de São Paulo (SP) | F24: Sim | G24: Sim | H24: B | I24: B | J24: CD 1A | K24: 765463 | L24: De 500 mil a 1 milhão | M24: 810729 | N24: De 500 mil a 1 milhão | O24: 841154 | P24: De 500 mil a 1 milhão | Q24: Sim | R24: Sim | S24: Sim | T24: 2022 | U24: Sim | V24: Lei Municipal | W24: 7113/2022 | X24: 44743 | Y24: https://we.tl/t-4E7JauxhaE | Z24: N:\a. DEPARTAMENTOS\i. DEPLAN\2.CGARG\SIMU\Levantamento Planos de Mobilidade\Planos Municipais - exemplos\SUDESTE\São Paulo\São Bernardo_do_campo_SP | AB24: Nao | AD24: Email | AE24: 44771 | AF24: secretariadetransportes@saobernardo.sp.gov.br | AG24: Sim | AH24: Sim | AI24: Sim
A25: 2408102 | B25: NE | C25: RN | D25: Natal | E25: RM de Natal (RN) | F25: Sim | G25: Sim | H25: #N/A | I25: A | J25: CD 1A | K25: 803739 | L25: De 500 mil a 1 milhão | M25: 751300 | N25: De 500 mil a 1 milhão | O25: 784249 | P25: De 500 mil a 1 milhão | Q25: Sim | R25: Sim | S25: Sim | T25: 2022 | U25: Sim | V25: Decreto Municipal | W25: 12540/2022 | X25: 44727 | Z25: N:\a. DEPARTAMENTOS\i. DEPLAN\2.CGARG\SIMU\Levantamento Planos de Mobilidade\Planos Municipais - exemplos\NORDESTE\Natal_RN | AB25: Nao | AD25: Leandro Martins | AE25: 44727 | AF25: Leandro Martins | AG25: Sim | AH25: Sim | AI25: Sim
A26: 3547809 | B26: SE | C26: SP | D26: Santo André | E26: RM de São Paulo (SP) | F26: Sim | G26: Sim | H26: B | I26: B | J26: CD 1A | K26: 676407 | L26: De 500 mil a 1 milhão | M26: 748919 | N26: De 500 mil a 1 milhão | O26: 782048 | P26: De 500 mil a 1 milhão | Q26: Sim | R26: Sim | S26: Sim | T26: 2023 | U26: Sim | V26: Lei Municipal | W26: 10736/2023 | X26: 45268 | Z26: N:\a. DEPARTAMENTOS\i. DEPLAN\2.CGARG\SIMU\Levantamento Planos de Mobilidade\Planos Municipais - exemplos\SUDESTE\São Paulo\Santo André_SP | AB26: Nao | AD26: Email; Ofício 210.12.2023 UGP | AE26: 45279 | AF26: Ugp@santoandre.sp.gov.br | AG26: Sim | AH26: Sim | AI26: Sim
A27: 3552205 | B27: SE | C27: SP | D27: Sorocaba | E27: RM de Sorocaba (SP) | F27: Não | G27: Nao | H27: B | I27: B | J27: CD 1A | K27: 586625 | L27: De 500 mil a 1 milhão | M27: 723682 | N27: De 500 mil a 1 milhão | O27: 762172 | P27: De 500 mil a 1 milhão | Q27: Sim | R27: Sim | S27: Sim | T27: 2016 | U27: Sim | V27: Lei Municipal | W27: 11319/2016 | X27: 42494 | Z27: \\londrina\SNTMU$\a. DEPARTAMENTOS\i. DEPLAN\2.CGARG\SIMU\Levantamento Planos de Mobilidade 2019\Planos Municipais - exemplos\SUDESTE\São Paulo\Sorocaba_SP | AB27: Nao | AD27: Pemob 2024 | AE27: 45530 | AF27: Pemob 2024 | AG27: Sim | AH27: Sim | AI27: Sim
A28: 3170206 | B28: SE | C28: MG | D28: Uberlândia | E28: #N/A | F28: Não | G28: Nao | H28: A | I28: A | J28: CD 2C | K28: 604013 | L28: De 500 mil a 1 milhão | M28: 713224 | N28: De 500 mil a 1 milhão | O28: 761835 | P28: De 500 mil a 1 milhão | Q28: Sim | R28: Sim | S28: Sim | T28: 2025 | U28: Sim | V28: Decreto Municipal | W28: 21768/2025 | X28: 45751 | Y28: http://www.uberlandia.mg.gov.br/uploads/cms_b_arquivos/17532.pdf http://www.uberlandia.mg.gov.br/uploads/cms_b_arquivos/17533.pdf | Z28: L:\a. DEPARTAMENTOS\i. DEPLAN\2.CGARG\SIMU\Levantamento Planos de Mobilidade 2019\Planos Municipais - exemplos\SUDESTE\Minas Gerais\Uberlândia_MG | AB28: Nao | AD28: E-mail | AE28: 45755 | AF28: gabrielamendes@uberlandia.mg.gov.br | AG28: Sim | AH28: Sim | AI28: Sim
A29: 3534401 | B29: SE | C29: SP | D29: Osasco | E29: RM de São Paulo (SP) | F29: Sim | G29: Sim | H29: B | I29: #N/A | J29: CD 1A | K29: 666740 | L29: De 500 mil a 1 milhão | M29: 728615 | N29: De 500 mil a 1 milhão | O29: 759524 | P29: De 500 mil a 1 milhão | Q29: Sim | R29: Sim | S29: Sim | T29: 2016 | U29: Sim | V29: Lei Municipal | W29: 4.765/2016 | X29: 42558 | Y29: http://www.seplag.osasco.sp.gov.br/Content/uploads/publicacao/arquivo/d36ab199-8d5d-4f05-8886-ad0caaab5910.pdf | Z29: \\londrina\SNTMU$\a. DEPARTAMENTOS\i. DEPLAN\2.CGARG\SIMU\Levantamento Planos de Mobilidade 2019\Planos Municipais - exemplos\SUDESTE\São Paulo\Osasco_SP | AB29: Nao | AD29: Ofício nº 13/2019 | AE29: 43621 | AF29: FNP | AG29: Sim | AH29: Sim | AI29: Sim
A30: 3543402 | B30: SE | C30: SP | D30: Ribeirão Preto | E30: RM de Ribeirão Preto (SP) | F30: Não | G30: Nao | H30: A | I30: A | J30: CD 2A | K30: 604682 | L30: De 500 mil a 1 milhão | M30: 698642 | N30: De 500 mil a 1 milhão | O30: 731639 | P30: De 500 mil a 1 milhão | Q30: Sim | R30: Sim | S30: Sim | T30: 2012 | U30: Nao | V30: Nao aprovado em lei | X30: Nao aprovado em lei | Y30: http://www.ribeiraopreto.sp.gov.br/transerp/mobilidade/i07mobilidade.php | Z30: \\londrina\SNTMU$\a. DEPARTAMENTOS\i. DEPLAN\2.CGARG\SIMU\Levantamento Planos de Mobilidade 2019\Planos Municipais - exemplos\SUDESTE\São Paulo\Ribeirão Preto_SP | AB30: Sim | AC30: 44652 | AD30: Ofício nº 01/2016 | AE30: 42416 | AF30: FNP | AG30: Sim | AH30: Sim | AI30: Sim
A31: 3549904 | B31: SE | C31: SP | D31: São José dos Campos | E31: RM do Vale do Paraíba e Litoral Norte (SP) | F31: Não | G31: Nao | H31: B | I31: B | J31: CD 1A | K31: 629921 | L31: De 500 mil a 1 milhão | M31: 697054 | N31: De 500 mil a 1 milhão | O31: 727078 | P31: De 500 mil a 1 milhão | Q31: Sim | R31: Sim | S31: Sim | T31: 2016 | U31: Sim | V31: Lei Complementar | W31: 576/2016 | X31: 42444 | Y31: http://www.sjc.sp.gov.br/servicos/mobilidade-urbana/lei-de-mobilidade-urbana/ | Z31: \\londrina\SNTMU$\a. DEPARTAMENTOS\i. DEPLAN\2.CGARG\SIMU\Levantamento Planos de Mobilidade 2019\Planos Municipais - exemplos\SUDESTE\São Paulo\São José dos Campos_SP | AB31: Nao | AD31: Ofício nº 01/2016 | AE31: 42475 | AF31: jobquim@sãojosédoscampos.sp.gov.br/servicos | AG31: Sim | AH31: Sim | AI31: Sim
A32: 5103403 | B32: CO | C32: MT | D32: Cuiabá | E32: RM do Vale do Rio Cuiabá (MT) | F32: Não | G32: Nao | H32: A | I32: A | J32: CD 1A | K32: 551098 | L32: De 500 mil a 1 milhão | M32: 650877 | N32: De 500 mil a 1 milhão | O32: 691875 | P32: De 500 mil a 1 milhão | Q32: Sim | R32: Sim | S32: Sim | T32: 2024 | U32: Sim | V32: Decreto Municipal | W32: 10776/2024 | X32: 45645 | Y32: https://leismunicipais.com.br/a/mt/c/cuiaba/decreto/2024/1078/10776/decreto-n-10776-2024-institui-o-plano-de-mobilidade-urbana-do-municipio-de-cuiaba-planmob-cuiaba-e-estabelece-diretrizes-para-o-acompanhamento-e-o-monitoramento-de-sua-implementacao-avaliacao-e-revisao-periodica?q=contas+anuais | Z32: N:\a. DEPARTAMENTOS\i. DEPLAN\2.CGARG\SIMU\Levantamento Planos de Mobilidade\Planos Municipais - exemplos\CENTRO-OESTE\Cuiabá_MT | AB32: Nao | AD32: Internet | AE32: 45954 | AF32: Casa Civil - Seleção Novo PAC | AG32: Sim | AH32: Sim | AI32: Sim
A33: 2607901 | B33: NE | C33: PE | D33: Jaboatão dos Guararapes | E33: RM de Recife (PE) | F33: Sim | G33: Sim | H33: B | I33: B | J33: CD 1A | K33: 644620 | L33: De 500 mil a 1 milhão | M33: 644037 | N33: De 500 mil a 1 milhão | O33: 684293 | P33: De 500 mil a 1 milhão | Q33: Sim | R33: Sim | S33: Sim | T33: 2022 | U33: Sim | V33: Lei Municipal | W33: 1538/2022 | X33: 44881 | Y33: - | Z33: N:\a. DEPARTAMENTOS\i. DEPLAN\2.CGARG\SIMU\Levantamento Planos de Mobilidade\Planos Municipais - exemplos\NORDESTE\JaboatãodosGuararapes_PE | AB33: Nao | AD33: Email | AE33: 44883 | AF33: julilinsfialho@gmail.com | AG33: Sim | AH33: Sim | AI33: Sim
A34: 4209102 | B34: S | C34: SC | D34: Joinville | E34: RM do Norte/Nordeste Catarinense (SC); RM de Joinville (SC) | F34: Não | G34: Nao | H34: A | I34: A | J34: CD 2A | K34: 515288 | L34: De 500 mil a 1 milhão | M34: 616317 | N34: De 500 mil a 1 milhão | O34: 664541 | P34: De 500 mil a 1 milhão | Q34: Sim | R34: Sim | S34: Sim | T34: 2015 | U34: Sim | V34: Decreto Municipal | W34: 24.181/2015 | X34: 42090 | Y34: https://www.joinville.sc.gov.br/publicacoes/plano-de-mobilidade-de-joinville-planmob/ | Z34: L:\a. DEPARTAMENTOS\i. DEPLAN\2.CGARG\SIMU\Levantamento Planos de Mobilidade 2019\Planos Municipais - exemplos\SUL\Santa Catarina\Joinville_SC | AB34: Nao | AD34: Ofício nº 13/2019 | AE34: 43612 | AF34: FNP | AG34: Sim | AH34: Sim | AI34: Sim
A35: 2910800 | B35: NE | C35: BA | D35: Feira de Santana | E35: RM de Feira de Santana (BA) | F35: Não | G35: Nao | H35: B | I35: #N/A | J35: CD 2C | K35: 556642 | L35: De 500 mil a 1 milhão | M35: 616272 | N35: De 500 mil a 1 milhão | O35: 660806 | P35: De 500 mil a 1 milhão | Q35: Sim | R35: Sim | S35: Sim | T35: 2018 | U35: Sim | V35: Lei Complementar | W35: 112/2018 | X35: 43195 | AB35: Nao | AD35: Pemob/2019 | AE35: 43809 | AF35: Pesquisa PlanMob 2019 | AG35: Sim | AH35: Sim | AI35: Sim
A36: 3118601 | B36: SE | C36: MG | D36: Contagem | E36: RM de Belo Horizonte (MG) | F36: Sim | G36: Sim | H36: #N/A | I36: B | J36: CD 1A | K36: 603442 | L36: De 500 mil a 1 milhão | M36: 621863 | N36: De 500 mil a 1 milhão | O36: 651718 | P36: De 500 mil a 1 milhão | Q36: Sim | R36: Sim | S36: Sim | T36: 2016 | U36: Sim | V36: Lei Municipal | W36: 4830/2016 | X36: 42520 | Y36: http://www.contagem.mg.gov.br/arquivos/legislacao/lei_0048302016.pdf | Z36: L:\a. DEPARTAMENTOS\i. DEPLAN\2.CGARG\SIMU\Levantamento Planos de Mobilidade 2019\Planos Municipais - exemplos\SUDESTE\Minas Gerais\Contagem_MG | AB36: Nao | AD36: Ofício nº 01/2016 | AE36: 42396 | AF36: CBTU | AG36: Sim | AH36: Sim | AI36: Sim
A37: 2800308 | B37: NE | C37: SE | D37: Aracaju | E37: RM de Aracaju (SE) | F37: Não | G37: Nao | H37: A | I37: A | J37: CD 1A | K37: 571149 | L37: De 500 mil a 1 milhão | M37: 602757 | N37: De 500 mil a 1 milhão | O37: 630932 | P37: De 500 mil a 1 milhão | Q37: Sim | R37: Sim | S37: Sim | T37: 2010 | U37: Nao | V37: Nao aprovado em lei | X37: Nao aprovado em lei | Y37: http://aracaju.se.gov.br/index.php?act=leitura&codigo=68200 | Z37: L:\a. DEPARTAMENTOS\i. DEPLAN\2.CGARG\SIMU\Levantamento Planos de Mobilidade 2019\Planos Municipais - exemplos\NORDESTE\Aracaju_SE | AB37: Em revisao | AC37: 42705 | AD37: Ofício nº 01/2016 | AE37: 42426 | AF37: nº 01/2016.gabinear@gmail.br | AG37: Sim | AH37: Sim | AI37: Sim
A38: 4205407 | B38: S | C38: SC | D38: Florianópolis | E38: RM de Florianópolis (SC) | F38: Sim | G38: Sim | H38: A | I38: A | J38: CD 1A | K38: 421240 | L38: De 250 mil a 500 mil | M38: 537211 | N38: De 500 mil a 1 milhão | O38: 587486 | P38: De 500 mil a 1 milhão | Q38: Sim | R38: Sim | S38: Sim | T38: 2015 | U38: Sim | V38: Decreto Municipal | W38: 27311/2024 | X38: 45646 | Z38: L:\a. DEPARTAMENTOS\i. DEPLAN\2.CGARG\SIMU\Levantamento Planos de Mobilidade 2019\Planos Municipais - exemplos\SUL\Santa Catarina\Florianópolis_SC | AB38: Nao | AD38: E-mail | AE38: 45650 | AF38: pescador.americo@gmail.com | AG38: Sim | AH38: Sim | AI38: Sim
A39: 4113700 | B39: S | C39: PR | D39: Londrina | E39: RM de Londrina (PR) | F39: Não | G39: Nao | H39: A | I39: A | J39: CD 2A | K39: 506701 | L39: De 500 mil a 1 milhão | M39: 555965 | N39: De 500 mil a 1 milhão | O39: 581382 | P39: De 500 mil a 1 milhão | Q39: Sim | R39: Sim | S39: Sim | T39: 2022 | U39: Sim | V39: Decreto Municipal | W39: 865/2022 | X39: 44409 | Y39: http://ippul.londrina.pr.gov.br/index.php/plano-de-mobilidade.html | Z39: file:///L:/a.%20DEPARTAMENTOS/i.%20DEPLAN/2.CGARG/SIMU/Levantamento%20Planos%20de%20Mobilidade/Planos%20Municipais%20-%20exemplos/SUL/Paraná/Londrina_PR/2_audiencia_publica_planmob.pdf | AB39: Nao | AD39: Pemob 2024 | AE39: 45502 | AF39: ippul.transito@londrina.pr.gov.br | AG39: Sim | AH39: Sim | AI39: Sim
A40: 3205002 | B40: SE | C40: ES | D40: Serra | E40: RM da Grande Vitória (ES) | F40: Sim | G40: Sim | H40: B | I40: B | J40: CD 1A | K40: 409267 | L40: De 250 mil a 500 mil | M40: 520653 | N40: De 500 mil a 1 milhão | O40: 579720 | P40: De 500 mil a 1 milhão | Q40: Sim | R40: Sim | S40: Sim | T40: 2024 | U40: Sim | V40: Lei Complementar | W40: 5590/2024 | X40: 45426 | Y40: https://prefeiturasempapel.serra.es.gov.br/Arquivo/Documents/legislacao/html/L59902024.html?identificador=3100340038003300330039003A004C00 | AB40: Nao | AD40: Pemob 2024 | AE40: 45541 | AG40: Sim | AH40: Sim | AI40: Sim
...

Sheet RMs
A1: UF | B1: RM | C1: Censo 2010 | D1: Censo 2022 | E1: Estimativa 2025 | H1: Censo 2010 | I1: Censo 2022 | J1: Estimativa 2025
A2: SP | B2: RM de São Paulo (SP) | C2: =SUMIF(Levantamento!$E$2:$E$5572,B2,Levantamento!$K$2:$K$5572) -> 19683975 | D2: =SUMIF(Levantamento!$E$2:$E$5572,B2,Levantamento!$M$2:$M$5572) -> 20731920 | E2: =SUMIF(Levantamento!$E$2:$E$5572,B2,Levantamento!$O$2:$O$5572) -> 21555260 | H2: =SUMIFS(Levantamento!$K$2:$K$5572,Levantamento!$E$2:$E$5572,B2,Levantamento!$G$2:$G$5572,"Sim") -> 18724542 | I2: =SUMIFS(Levantamento!$M$2:$M$5572,Levantamento!$E$2:$E$5572,B2,Levantamento!$G$2:$G$5572,"Sim") -> 19672108 | J2: =SUMIFS(Levantamento!$O$2:$O$5572,Levantamento!$E$2:$E$5572,B2,Levantamento!$G$2:$G$5572,"Sim") -> 20456622
A3: RJ | B3: RM do Rio de Janeiro (RJ) | C3: =SUMIF(Levantamento!$E$2:$E$5572,B3,Levantamento!$K$2:$K$5572) -> 12241449 | D3: =SUMIF(Levantamento!$E$2:$E$5572,B3,Levantamento!$M$2:$M$5572) -> 12021871 | E3: =SUMIF(Levantamento!$E$2:$E$5572,B3,Levantamento!$O$2:$O$5572) -> 12937950 | H3: =SUMIFS(Levantamento!$K$2:$K$5572, Levantamento!$E$2:$E$5572,B3, Levantamento!$G$2:$G$5572,"Sim") -> 11119113 | I3: =SUMIFS(Levantamento!$M$2:$M$5572,Levantamento!$E$2:$E$5572,B3,Levantamento!$G$2:$G$5572,"Sim") -> 10898794 | J3: =SUMIFS(Levantamento!$O$2:$O$5572,Levantamento!$E$2:$E$5572,B3,Levantamento!$G$2:$G$5572,"Sim") -> 11747297
A4: MG | B4: RM de Belo Horizonte (MG) | C4: =SUMIF(Levantamento!$E$2:$E$5572,B4,Levantamento!$K$2:$K$5572) -> 4883970 | D4: =SUMIF(Levantamento!$E$2:$E$5572,B4,Levantamento!$M$2:$M$5572) -> 5128282 | E4: =SUMIF(Levantamento!$E$2:$E$5572,B4,Levantamento!$O$2:$O$5572) -> 5383386 | H4: =SUMIFS(Levantamento!$K$2:$K$5572,Levantamento!$E$2:$E$5572,B4,Levantamento!$G$2:$G$5572,"Sim") -> 4326689 | I4: =SUMIFS(Levantamento!$M$2:$M$5572,Levantamento!$E$2:$E$5572,B4,Levantamento!$G$2:$G$5572,"Sim") -> 4438830 | J4: =SUMIFS(Levantamento!$O$2:$O$5572,Levantamento!$E$2:$E$5572,B4,Levantamento!$G$2:$G$5572,"Sim") -> 4650076
A5: RS | B5: RM de Porto Alegre (RS) | C5: =SUMIF(Levantamento!$E$2:$E$5572,B5,Levantamento!$K$2:$K$5572) -> 4032062 | D5: =SUMIF(Levantamento!$E$2:$E$5572,B5,Levantamento!$M$2:$M$5572) -> 4019420 | E5: =SUMIF(Levantamento!$E$2:$E$5572,B5,Levantamento!$O$2:$O$5572) -> 4167509 | H5: =SUMIFS(Levantamento!$K$2:$K$5572,Levantamento!$E$2:$E$5572,B5,Levantamento!$G$2:$G$5572,"Sim") -> 3206912 | I5: =SUMIFS(Levantamento!$M$2:$M$5572,Levantamento!$E$2:$E$5572,B5,Levantamento!$G$2:$G$5572,"Sim") -> 3146560 | J5: =SUMIFS(Levantamento!$O$2:$O$5572,Levantamento!$E$2:$E$5572,B5,Levantamento!$G$2:$G$5572,"Sim") -> 3267880
A6: CE | B6: RM de Fortaleza (CE) | C6: =SUMIF(Levantamento!$E$2:$E$5572,B6,Levantamento!$K$2:$K$5572) -> 3741198 | D6: =SUMIF(Levantamento!$E$2:$E$5572,B6,Levantamento!$M$2:$M$5572) -> 3905891 | E6: =SUMIF(Levantamento!$E$2:$E$5572,B6,Levantamento!$O$2:$O$5572) -> 4154961 | H6: =SUMIFS(Levantamento!$K$2:$K$5572,Levantamento!$E$2:$E$5572,B6,Levantamento!$G$2:$G$5572,"Sim") -> 3291204 | I6: =SUMIFS(Levantamento!$M$2:$M$5572,Levantamento!$E$2:$E$5572,B6,Levantamento!$G$2:$G$5572,"Sim") -> 3360328 | J6: =SUMIFS(Levantamento!$O$2:$O$5572,Levantamento!$E$2:$E$5572,B6,Levantamento!$G$2:$G$5572,"Sim") -> 3571020
A7: PE | B7: RM de Recife (PE) | C7: =SUMIF(Levantamento!$E$2:$E$5572,B7,Levantamento!$K$2:$K$5572) -> 3690547 | D7: =SUMIF(Levantamento!$E$2:$E$5572,B7,Levantamento!$M$2:$M$5572) -> 3726974 | E7: =SUMIF(Levantamento!$E$2:$E$5572,B7,Levantamento!$O$2:$O$5572) -> 3961730 | H7: =SUMIFS(Levantamento!$K$2:$K$5572,Levantamento!$E$2:$E$5572,B7,Levantamento!$G$2:$G$5572,"Sim") -> 3489405 | I7: =SUMIFS(Levantamento!$K$2:$K$5572,Levantamento!$E$2:$E$5572,B7,Levantamento!$G$2:$G$5572,"Sim") -> 3489405 | J7: =SUMIFS(Levantamento!$O$2:$O$5572,Levantamento!$E$2:$E$5572,B7,Levantamento!$G$2:$G$5572,"Sim") -> 3722214
A8: PR | B8: RM de Curitiba (PR) | C8: =SUMIF(Levantamento!$E$2:$E$5572,B8,Levantamento!$K$2:$K$5572) -> 3223836 | D8: =SUMIF(Levantamento!$E$2:$E$5572,B8,Levantamento!$M$2:$M$5572) -> 3560258 | E8: =SUMIF(Levantamento!$E$2:$E$5572,B8,Levantamento!$O$2:$O$5572) -> 3720170 | H8: =SUMIFS(Levantamento!$K$2:$K$5572,Levantamento!$E$2:$E$5572,B8,Levantamento!$G$2:$G$5572,"Sim") -> 2855678 | I8: =SUMIFS(Levantamento!$M$2:$M$5572,Levantamento!$E$2:$E$5572,B8,Levantamento!$G$2:$G$5572,"Sim") -> 3137998 | J8: =SUMIFS(Levantamento!$O$2:$O$5572,Levantamento!$E$2:$E$5572,B8,Levantamento!$G$2:$G$5572,"Sim") -> 3279590
A9: BA | B9: RM de Salvador (BA) | C9: =SUMIF(Levantamento!$E$2:$E$5572,B9,Levantamento!$K$2:$K$5572) -> 3573973 | D9: =SUMIF(Levantamento!$E$2:$E$5572,B9,Levantamento!$M$2:$M$5572) -> 3415022 | E9: =SUMIF(Levantamento!$E$2:$E$5572,B9,Levantamento!$O$2:$O$5572) -> 3623330 | H9: =SUMIFS(Levantamento!$K$2:$K$5572,Levantamento!$E$2:$E$5572,B9,Levantamento!$G$2:$G$5572,"Sim") -> 3220847 | I9: =SUMIFS(Levantamento!$M$2:$M$5572,Levantamento!$E$2:$E$5572,B9,Levantamento!$G$2:$G$5572,"Sim") -> 3055729 | J9: =SUMIFS(Levantamento!$O$2:$O$5572,Levantamento!$E$2:$E$5572,B9,Levantamento!$G$2:$G$5572,"Sim") -> 3246176
A10: DF | B10: RIDE do Distrito Federal e Entorno | C10: =SUMIF(Levantamento!$E$2:$E$5572,B10,Levantamento!$K$2:$K$5572)+SUMIF(Levantamento!$E$2:$E$5572,"RIDE do Distrito Federal e Entorno_RM do Entorno do Distrito Federal",Levantamento!$K$2:$K$5572) -> 2956360 | D10: =SUMIF(Levantamento!$E$2:$E$5572,B10,Levantamento!$M$2:$M$5572)+SUMIF(Levantamento!$E$2:$E$5572,"RIDE do Distrito Federal e Entorno_RM do Entorno do Distrito Federal",Levantamento!$M$2:$M$5572) -> 3239483 | E10: =SUMIF(Levantamento!$E$2:$E$5572,B10,Levantamento!$O$2:$O$5572)+SUMIF(Levantamento!$E$2:$E$5572,"RIDE do Distrito Federal e Entorno_RM do Entorno do Distrito Federal",Levantamento!$O$2:$O$5572) -> 3434812 | H10: =SUMIFS(Levantamento!$K$2:$K$5572,Levantamento!$E$2:$E$5572,B10,Levantamento!$G$2:$G$5572,"Sim")+SUMIFS(Levantamento!$K$2:$K$5572,Levantamento!$E$2:$E$5572,"RIDE do Distrito Federal e Entorno_RM do Entorno do Distrito Federal",Levantamento!$G$2:$G$5572,"Sim") -> 2570160 | I10: =SUMIFS(Levantamento!$M$2:$M$5572,Levantamento!$E$2:$E$5572,B10,Levantamento!$G$2:$G$5572,"Sim")+SUMIFS(Levantamento!$M$2:$M$5572,Levantamento!$E$2:$E$5572,"RIDE do Distrito Federal e Entorno_RM do Entorno do Distrito Federal",Levantamento!$G$2:$G$5572,"Sim") -> 2817381 | J10: =SUMIFS(Levantamento!$O$2:$O$5572,Levantamento!$E$2:$E$5572,B10,Levantamento!$G$2:$G$5572,"Sim")+SUMIFS(Levantamento!$O$2:$O$5572,Levantamento!$E$2:$E$5572,"RIDE do Distrito Federal e Entorno_RM do Entorno do Distrito Federal",Levantamento!$G$2:$G$5572,"Sim") -> 2996899
A11: SP | B11: RM de Campinas (SP) | C11: =SUMIF(Levantamento!$E$2:$E$5572,B11,Levantamento!$K$2:$K$5572) -> 2808906 | D11: =SUMIF(Levantamento!$E$2:$E$5572,B11,Levantamento!$M$2:$M$5572) -> 3178601 | E11: =SUMIF(Levantamento!$E$2:$E$5572,B11,Levantamento!$O$2:$O$5572) -> 3317498 | H11: =SUMIFS(Levantamento!$K$2:$K$5572,Levantamento!$E$2:$E$5572,B11,Levantamento!$G$2:$G$5572,"Sim") -> 2208555 | I11: =SUMIFS(Levantamento!$M$2:$M$5572,Levantamento!$E$2:$E$5572,B11,Levantamento!$G$2:$G$5572,"Sim") -> 2451289 | J11: =SUMIFS(Levantamento!$O$2:$O$5572,Levantamento!$E$2:$E$5572,B11,Levantamento!$G$2:$G$5572,"Sim") -> 2557576
A12: GO | B12: RM de Goiânia (GO) | C12: =SUMIF(Levantamento!$E$2:$E$5572,B12,Levantamento!$K$2:$K$5572) -> 2178892 | D12: =SUMIF(Levantamento!$E$2:$E$5572,B12,Levantamento!$M$2:$M$5572) -> 2600936 | E12: =SUMIF(Levantamento!$E$2:$E$5572,B12,Levantamento!$O$2:$O$5572) -> 2754016 | H12: =SUMIFS(Levantamento!$K$2:$K$5572,Levantamento!$E$2:$E$5572,B12,Levantamento!$G$2:$G$5572,"Sim") -> 1980649 | I12: =SUMIFS(Levantamento!$M$2:$M$5572,Levantamento!$E$2:$E$5572,B12,Levantamento!$G$2:$G$5572,"Sim") -> 2335144 | J12: =SUMIFS(Levantamento!$O$2:$O$5572,Levantamento!$E$2:$E$5572,B12,Levantamento!$G$2:$G$5572,"Sim") -> 2469374
A13: AM | B13: RM de Manaus (AM) | C13: =SUMIF(Levantamento!$E$2:$E$5572,B13,Levantamento!$K$2:$K$5572) -> 2210647 | D13: =SUMIF(Levantamento!$E$2:$E$5572,B13,Levantamento!$M$2:$M$5572) -> 2532519 | E13: =SUMIF(Levantamento!$E$2:$E$5572,B13,Levantamento!$O$2:$O$5572) -> 2811884 | H13: =SUMIFS(Levantamento!$K$2:$K$5572,Levantamento!$E$2:$E$5572,B13,Levantamento!$G$2:$G$5572,"Sim") -> 1802014 | I13: =SUMIFS(Levantamento!$M$2:$M$5572,Levantamento!$E$2:$E$5572,B13,Levantamento!$G$2:$G$5572,"Sim") -> 2063689 | J13: =SUMIFS(Levantamento!$O$2:$O$5572,Levantamento!$E$2:$E$5572,B13,Levantamento!$G$2:$G$5572,"Sim") -> 2303732
A14: SP | B14: RM do Vale do Paraíba e Litoral Norte (SP) | C14: =SUMIF(Levantamento!$E$2:$E$5572,B14,Levantamento!$K$2:$K$5572) -> 2264594 | D14: =SUMIF(Levantamento!$E$2:$E$5572,B14,Levantamento!$M$2:$M$5572) -> 2505723 | E14: =SUMIF(Levantamento!$E$2:$E$5572,B14,Levantamento!$O$2:$O$5572) -> 2601680
A15: PA | B15: RM de Belém (PA) | C15: =SUMIF(Levantamento!$E$2:$E$5572,B15,Levantamento!$K$2:$K$5572) -> 2374891 | D15: =SUMIF(Levantamento!$E$2:$E$5572,B15,Levantamento!$M$2:$M$5572) -> 2370545 | E15: =SUMIF(Levantamento!$E$2:$E$5572,B15,Levantamento!$O$2:$O$5572) -> 2544868 | H15: =SUMIFS(Levantamento!$K$2:$K$5572,Levantamento!$E$2:$E$5572,B15,Levantamento!$G$2:$G$5572,"Sim") -> 2025276 | I15: =SUMIFS(Levantamento!$M$2:$M$5572,Levantamento!$E$2:$E$5572,B15,Levantamento!$G$2:$G$5572,"Sim") -> 1957533 | J15: =SUMIFS(Levantamento!$O$2:$O$5572,Levantamento!$E$2:$E$5572,B15,Levantamento!$G$2:$G$5572,"Sim") -> 2094941
A16: SP | B16: RM de Sorocaba (SP) | C16: =SUMIF(Levantamento!$E$2:$E$5572,B16,Levantamento!$K$2:$K$5572) -> 1871162 | D16: =SUMIF(Levantamento!$E$2:$E$5572,B16,Levantamento!$M$2:$M$5572) -> 2174525 | E16: =SUMIF(Levantamento!$E$2:$E$5572,B16,Levantamento!$O$2:$O$5572) -> 2268579
A17: ES | B17: RM da Grande Vitória (ES) | C17: =SUMIF(Levantamento!$E$2:$E$5572,B17,Levantamento!$K$2:$K$5572) -> 1687704 | D17: =SUMIF(Levantamento!$E$2:$E$5572,B17,Levantamento!$M$2:$M$5572) -> 1880828 | E17: =SUMIF(Levantamento!$E$2:$E$5572,B17,Levantamento!$O$2:$O$5572) -> 2040329 | H17: =SUMIFS(Levantamento!$K$2:$K$5572,Levantamento!$E$2:$E$5572,B17,Levantamento!$G$2:$G$5572,"Sim") -> 1565393 | I17: =SUMIFS(Levantamento!$M$2:$M$5572,Levantamento!$E$2:$E$5572,B17,Levantamento!$G$2:$G$5572,"Sim") -> 1738158 | J17: =SUMIFS(Levantamento!$O$2:$O$5572,Levantamento!$E$2:$E$5572,B17,Levantamento!$G$2:$G$5572,"Sim") -> 1885120
A18: SP | B18: RM da Baixada Santista (SP) | C18: =SUMIF(Levantamento!$E$2:$E$5572,B18,Levantamento!$K$2:$K$5572) -> 1664136 | D18: =SUMIF(Levantamento!$E$2:$E$5572,B18,Levantamento!$M$2:$M$5572) -> 1805531 | E18: =SUMIF(Levantamento!$E$2:$E$5572,B18,Levantamento!$O$2:$O$5572) -> 1867558 | H18: =SUMIFS(Levantamento!$K$2:$K$5572,Levantamento!$E$2:$E$5572,B18,Levantamento!$G$2:$G$5572,"Sim") -> 1423368 | I18: =SUMIFS(Levantamento!$M$2:$M$5572,Levantamento!$E$2:$E$5572,B18,Levantamento!$G$2:$G$5572,"Sim") -> 1498564 | J18: =SUMIFS(Levantamento!$O$2:$O$5572,Levantamento!$E$2:$E$5572,B18,Levantamento!$G$2:$G$5572,"Sim") -> 1546153
A19: SP | B19: RM de Ribeirão Preto (SP) | C19: =SUMIF(Levantamento!$E$2:$E$5572,B19,Levantamento!$K$2:$K$5572) -> 1511140 | D19: =SUMIF(Levantamento!$E$2:$E$5572,B19,Levantamento!$M$2:$M$5572) -> 1648111 | E19: =SUMIF(Levantamento!$E$2:$E$5572,B19,Levantamento!$O$2:$O$5572) -> 1707166
A20: MA | B20: RM da Grande São Luís (MA) | C20: =SUMIF(Levantamento!$E$2:$E$5572,B20,Levantamento!$K$2:$K$5572) -> 1492370 | D20: =SUMIF(Levantamento!$E$2:$E$5572,B20,Levantamento!$M$2:$M$5572) -> 1646005 | E20: =SUMIF(Levantamento!$E$2:$E$5572,B20,Levantamento!$O$2:$O$5572) -> 1726262 | H20: =SUMIFS(Levantamento!$K$2:$K$5572,Levantamento!$E$2:$E$5572,B20,Levantamento!$G$2:$G$5572,"Sim") -> 1309330 | I20: =SUMIFS(Levantamento!$M$2:$M$5572,Levantamento!$E$2:$E$5572,B20,Levantamento!$G$2:$G$5572,"Sim") -> 1458836 | J20: =SUMIFS(Levantamento!$O$2:$O$5572,Levantamento!$E$2:$E$5572,B20,Levantamento!$G$2:$G$5572,"Sim") -> 1533693
A21: RN | B21: RM de Natal (RN) | C21: =SUMIF(Levantamento!$E$2:$E$5572,B21,Levantamento!$K$2:$K$5572) -> 1418461 | D21: =SUMIF(Levantamento!$E$2:$E$5572,B21,Levantamento!$M$2:$M$5572) -> 1527661 | E21: =SUMIF(Levantamento!$E$2:$E$5572,B21,Levantamento!$O$2:$O$5572) -> 1613858 | H21: =SUMIFS(Levantamento!$K$2:$K$5572,Levantamento!$E$2:$E$5572,B21,Levantamento!$G$2:$G$5572,"Sim") -> 1187899 | I21: =SUMIFS(Levantamento!$M$2:$M$5572,Levantamento!$E$2:$E$5572,B21,Levantamento!$G$2:$G$5572,"Sim") -> 1263738 | J21: =SUMIFS(Levantamento!$O$2:$O$5572,Levantamento!$E$2:$E$5572,B21,Levantamento!$G$2:$G$5572,"Sim") -> 1336097
A22: SP | B22: RM de Piracicaba (SP) | C22: =SUMIF(Levantamento!$E$2:$E$5572,B22,Levantamento!$K$2:$K$5572) -> 1381339 | D22: =SUMIF(Levantamento!$E$2:$E$5572,B22,Levantamento!$M$2:$M$5572) -> 1519024 | E22: =SUMIF(Levantamento!$E$2:$E$5572,B22,Levantamento!$O$2:$O$5572) -> 1572980
A23: SC | B23: RM do Norte/Nordeste Catarinense (SC) | C23: =SUMIF(Levantamento!$E$2:$E$5572,B23,Levantamento!$K$2:$K$5572)+SUMIF(Levantamento!$E$2:$E$5572,"RM do Norte/Nordeste Catarinense (SC); RM de Joinville (SC)",Levantamento!$K$2:$K$5572)+SUMIF(Levantamento!$E$2:$E$5572,"RM do Norte/Nordeste Catarinense (SC); RM de Jaraguá do Sul (SC)",Levantamento!$K$2:$K$5572)+SUMIF(Levantamento!$E$2:$E$5572,"RM do Norte/Nordeste Catarinense (SC); RM do Planalto Norte (SC)",Levantamento!$K$2:$K$5572) -> 1222730 | D23: =SUMIF(Levantamento!$E$2:$E$5572,B23,Levantamento!$M$2:$M$5572)+SUMIF(Levantamento!$E$2:$E$5572,"RM do Norte/Nordeste Catarinense (SC); RM de Joinville (SC)",Levantamento!$M$2:$M$5572)+SUMIF(Levantamento!$E$2:$E$5572,"RM do Norte/Nordeste Catarinense (SC); RM de Jaraguá do Sul (SC)",Levantamento!$M$2:$M$5572)+SUMIF(Levantamento!$E$2:$E$5572,"RM do Norte/Nordeste Catarinense (SC); RM do Planalto Norte (SC)",Levantamento!$M$2:$M$5572) -> 1480750 | E23: =SUMIF(Levantamento!$E$2:$E$5572,B23,Levantamento!$O$2:$O$5572)+SUMIF(Levantamento!$E$2:$E$5572,"RM do Norte/Nordeste Catarinense (SC); RM de Joinville (SC)",Levantamento!$O$2:$O$5572)+SUMIF(Levantamento!$E$2:$E$5572,"RM do Norte/Nordeste Catarinense (SC); RM de Jaraguá do Sul (SC)",Levantamento!$O$2:$O$5572)+SUMIF(Levantamento!$E$2:$E$5572,"RM do Norte/Nordeste Catarinense (SC); RM do Planalto Norte (SC)",Levantamento!$O$2:$O$5572) -> 1593700
A24: SC | B24: RM de Florianópolis (SC) | C24: =SUMIF(Levantamento!$E$2:$E$5572,B24,Levantamento!$K$2:$K$5572) -> 1012233 | D24: =SUMIF(Levantamento!$E$2:$E$5572,B24,Levantamento!$M$2:$M$5572) -> 1356861 | E24: =SUMIF(Levantamento!$E$2:$E$5572,B24,Levantamento!$O$2:$O$5572) -> 1493879 | H24: =SUMIFS(Levantamento!$K$2:$K$5572,Levantamento!$E$2:$E$5572,B24,Levantamento!$G$2:$G$5572,"Sim") -> 826584 | I24: =SUMIFS(Levantamento!$M$2:$M$5572,Levantamento!$E$2:$E$5572,B24,Levantamento!$G$2:$G$5572,"Sim") -> 1106881 | J24: =SUMIFS(Levantamento!$O$2:$O$5572,Levantamento!$E$2:$E$5572,B24,Levantamento!$G$2:$G$5572,"Sim") -> 1220369
A25: PB | B25: RM de João Pessoa (PB) | C25: =SUMIF(Levantamento!$E$2:$E$5572,B25,Levantamento!$K$2:$K$5572) -> 1156273 | D25: =SUMIF(Levantamento!$E$2:$E$5572,B25,Levantamento!$M$2:$M$5572) -> 1304280 | E25: =SUMIF(Levantamento!$E$2:$E$5572,B25,Levantamento!$O$2:$O$5572) -> 1393026 | H25: =SUMIFS(Levantamento!$K$2:$K$5572,Levantamento!$E$2:$E$5572,B25,Levantamento!$G$2:$G$5572,"Sim") -> 1001485 | I25: =SUMIFS(Levantamento!$M$2:$M$5572,Levantamento!$E$2:$E$5572,B25,Levantamento!$G$2:$G$5572,"Sim") -> 1133103 | J25: =SUMIFS(Levantamento!$O$2:$O$5572,Levantamento!$E$2:$E$5572,B25,Levantamento!$G$2:$G$5572,"Sim") -> 1213081
A26: AL | B26: RM de Maceió (AL) | C26: =SUMIF(Levantamento!$E$2:$E$5572,B26,Levantamento!$K$2:$K$5572) -> 1227396 | D26: =SUMIF(Levantamento!$E$2:$E$5572,B26,Levantamento!$M$2:$M$5572) -> 1300609 | E26: =SUMIF(Levantamento!$E$2:$E$5572,B26,Levantamento!$O$2:$O$5572) -> 1348674 | H26: =SUMIFS(Levantamento!$K$2:$K$5572,Levantamento!$E$2:$E$5572,B26,Levantamento!$G$2:$G$5572,"Sim") -> 1015832 | I26: =SUMIFS(Levantamento!$M$2:$M$5572,Levantamento!$E$2:$E$5572,B26,Levantamento!$G$2:$G$5572,"Sim") -> 1076121 | J26: =SUMIFS(Levantamento!$O$2:$O$5572,Levantamento!$E$2:$E$5572,B26,Levantamento!$G$2:$G$5572,"Sim") -> 1117715
A27: PI_MA | B27: RIDE da Grande Teresina (PI/MA) | C27: =SUMIF(Levantamento!$E$2:$E$5572,B26,Levantamento!$K$2:$K$5572)+SUMIF(Levantamento!$E$2:$E$5572,"RIDE da Grande Teresina (PI/MA); RM da Zona Leste do Estado do Maranhão (MA)",Levantamento!$K$2:$K$5572) -> 1382856 | D27: =SUMIF(Levantamento!$E$2:$E$5572,B27,Levantamento!$M$2:$M$5572)+SUMIF(Levantamento!$E$2:$E$5572,"RIDE da Grande Teresina (PI/MA); RM da Zona Leste do Estado do Maranhão (MA)",Levantamento!$M$2:$M$5572) -> 1246608 | E27: =SUMIF(Levantamento!$E$2:$E$5572,B27,Levantamento!$O$2:$O$5572)+SUMIF(Levantamento!$E$2:$E$5572,"RIDE da Grande Teresina (PI/MA); RM da Zona Leste do Estado do Maranhão (MA)",Levantamento!$O$2:$O$5572) -> 1303288 | H27: =SUMIFS(Levantamento!$K$2:$K$5572,Levantamento!$E$2:$E$5572,B26,Levantamento!$G$2:$G$5572,"Sim")+SUMIFS(Levantamento!$K$2:$K$5572,Levantamento!$E$2:$E$5572,"RIDE da Grande Teresina (PI/MA); RM da Zona Leste do Estado do Maranhão (MA)",Levantamento!$G$2:$G$5572,"Sim") -> 1171292 | I27: =SUMIFS(Levantamento!$M$2:$M$5572,Levantamento!$E$2:$E$5572,B27,Levantamento!$G$2:$G$5572,"Sim")+SUMIFS(Levantamento!$M$2:$M$5572,Levantamento!$E$2:$E$5572,"RIDE da Grande Teresina (PI/MA); RM da Zona Leste do Estado do Maranhão (MA)",Levantamento!$G$2:$G$5572,"Sim") -> 1040765 | J27: =SUMIFS(Levantamento!$O$2:$O$5572,Levantamento!$E$2:$E$5572,B27,Levantamento!$G$2:$G$5572,"Sim")+SUMIFS(Levantamento!$O$2:$O$5572,Levantamento!$E$2:$E$5572,"RIDE da Grande Teresina (PI/MA); RM da Zona Leste do Estado do Maranhão (MA)",Levantamento!$G$2:$G$5572,"Sim") -> 1088403
A28: DF | B28: RM do Entorno do Distrito Federal | C28: =SUMIF(Levantamento!$E$2:$E$5572,B28,Levantamento!$K$2:$K$5572)+SUMIF(Levantamento!$E$2:$E$5572,"RIDE do Distrito Federal e Entorno; RM do Entorno do Distrito Federal",Levantamento!$K$2:$K$5572) -> 954464 | D28: =SUMIF(Levantamento!$E$2:$E$5572,B28,Levantamento!$M$2:$M$5572)+SUMIF(Levantamento!$E$2:$E$5572,"RIDE do Distrito Federal e Entorno; RM do Entorno do Distrito Federal",Levantamento!$M$2:$M$5572) -> 1244633 | E28: =SUMIF(Levantamento!$E$2:$E$5572,B28,Levantamento!$O$2:$O$5572)+SUMIF(Levantamento!$E$2:$E$5572,"RIDE do Distrito Federal e Entorno; RM do Entorno do Distrito Federal",Levantamento!$O$2:$O$5572) -> 1334577
A29: PR | B29: RM de Londrina (PR) | C29: =SUMIF(Levantamento!$E$2:$E$5572,B29,Levantamento!$K$2:$K$5572) -> 1000062 | D29: =SUMIF(Levantamento!$E$2:$E$5572,B29,Levantamento!$M$2:$M$5572) -> 1088734 | E29: =SUMIF(Levantamento!$E$2:$E$5572,B29,Levantamento!$O$2:$O$5572) -> 1131313
A30: MT | B30: RM do Vale do Rio Cuiabá (MT) | C30: =SUMIF(Levantamento!$E$2:$E$5572,B30,Levantamento!$K$2:$K$5572) -> 888692 | D30: =SUMIF(Levantamento!$E$2:$E$5572,B30,Levantamento!$M$2:$M$5572) -> 1047730 | E30: =SUMIF(Levantamento!$E$2:$E$5572,B30,Levantamento!$O$2:$O$5572) -> 1112753 | H30: =SUMIF(Levantamento!D2:D5572,Levantamento!D32,Levantamento!K2:K5572)+SUMIF(Levantamento!D2:D5572,Levantamento!D94,Levantamento!K2:K5572) -> 808030 | I30: =SUMIF(Levantamento!D2:D5572,Levantamento!D32,Levantamento!M2:M5572)+SUMIF(Levantamento!D2:D5572,Levantamento!D94,Levantamento!M2:M5572) -> 955372 | J30: =SUMIF(Levantamento!D2:D5572,Levantamento!D32,Levantamento!O2:O5572)+SUMIF(Levantamento!D2:D5572,Levantamento!D94,Levantamento!O2:O5572) -> 1015317
A31: SP | B31: RM de São José do Rio Preto (SP) | C31: =SUMIF(Levantamento!$E$2:$E$5572,B31,Levantamento!$K$2:$K$5572) -> 840133 | D31: =SUMIF(Levantamento!$E$2:$E$5572,B31,Levantamento!$M$2:$M$5572) -> 971097 | E31: =SUMIF(Levantamento!$E$2:$E$5572,B31,Levantamento!$O$2:$O$5572) -> 1010633
A32: SE | B32: RM de Aracaju (SE) | C32: =SUMIF(Levantamento!$E$2:$E$5572,B32,Levantamento!$K$2:$K$5572) -> 835816 | D32: =SUMIF(Levantamento!$E$2:$E$5572,B32,Levantamento!$M$2:$M$5572) -> 932210 | E32: =SUMIF(Levantamento!$E$2:$E$5572,B32,Levantamento!$O$2:$O$5572) -> 981401
A33: SC | B33: RM de Joinville (SC) | C33: =SUMIF(Levantamento!$E$2:$E$5572,B33,Levantamento!$K$2:$K$5572)+SUMIF(Levantamento!$E$2:$E$5572,"RM do Norte/Nordeste Catarinense (SC); RM de Joinville (SC)",Levantamento!$K$2:$K$5572) -> 746967 | D33: =SUMIF(Levantamento!$E$2:$E$5572,B33,Levantamento!$M$2:$M$5572)+SUMIF(Levantamento!$E$2:$E$5572,"RM do Norte/Nordeste Catarinense (SC); RM de Joinville (SC)",Levantamento!$M$2:$M$5572) -> 913520 | E33: =SUMIF(Levantamento!$E$2:$E$5572,B33,Levantamento!$O$2:$O$5572)+SUMIF(Levantamento!$E$2:$E$5572,"RM do Norte/Nordeste Catarinense (SC); RM de Joinville (SC)",Levantamento!$O$2:$O$5572) -> 986981
A34: PR | B34: RM de Maringá (PR) | C34: =SUMIF(Levantamento!$E$2:$E$5572,B34,Levantamento!$K$2:$K$5572) -> 716918 | D34: =SUMIF(Levantamento!$E$2:$E$5572,B34,Levantamento!$M$2:$M$5572) -> 851829 | E34: =SUMIF(Levantamento!$E$2:$E$5572,B34,Levantamento!$O$2:$O$5572) -> 896763
A35: SP | B35: RM de Jundiaí (SP) | C35: =SUMIF(Levantamento!$E$2:$E$5572,B35,Levantamento!$K$2:$K$5572) -> 698724 | D35: =SUMIF(Levantamento!$E$2:$E$5572,B35,Levantamento!$M$2:$M$5572) -> 843633 | E35: =SUMIF(Levantamento!$E$2:$E$5572,B35,Levantamento!$O$2:$O$5572) -> 880995
A36: SC | B36: RM do Vale Europeu (SC) | C36: =SUMIF(Levantamento!$E$2:$E$5572,B36,Levantamento!$K$2:$K$5572) -> 689731 | D36: =SUMIF(Levantamento!$E$2:$E$5572,B36,Levantamento!$M$2:$M$5572) -> 841698 | E36: =SUMIF(Levantamento!$E$2:$E$5572,B36,Levantamento!$O$2:$O$5572) -> 905047
A37: BA_PE | B37: RIDE do Polo Petrolina/PE e Juazeiro/BA | C37: =SUMIF(Levantamento!$E$2:$E$5572,B37,Levantamento!$K$2:$K$5572) -> 686410 | D37: =SUMIF(Levantamento!$E$2:$E$5572,B37,Levantamento!$M$2:$M$5572) -> 834632 | E37: =SUMIF(Levantamento!$E$2:$E$5572,B37,Levantamento!$O$2:$O$5572) -> 895783
A38: RS | B38: RM da Serra Gaúcha (RS) | C38: =SUMIF(Levantamento!$E$2:$E$5572,B38,Levantamento!$K$2:$K$5572) -> 738619 | D38: =SUMIF(Levantamento!$E$2:$E$5572,B38,Levantamento!$M$2:$M$5572) -> 804707 | E38: =SUMIF(Levantamento!$E$2:$E$5572,B38,Levantamento!$O$2:$O$5572) -> 832518
A39: SC | B39: RM da Foz do Rio Itajaí (SC) | C39: =SUMIF(Levantamento!$E$2:$E$5572,B39,Levantamento!$K$2:$K$5572) -> 532771 | D39: =SUMIF(Levantamento!$E$2:$E$5572,B39,Levantamento!$M$2:$M$5572) -> 782160 | E39: =SUMIF(Levantamento!$E$2:$E$5572,B39,Levantamento!$O$2:$O$5572) -> 873893
A40: BA | B40: RM de Feira de Santana (BA) | C40: =SUMIF(Levantamento!$E$2:$E$5572,B40,Levantamento!$K$2:$K$5572) -> 673637 | D40: =SUMIF(Levantamento!$E$2:$E$5572,B40,Levantamento!$M$2:$M$5572) -> 743748 | E40: =SUMIF(Levantamento!$E$2:$E$5572,B40,Levantamento!$O$2:$O$5572) -> 794949
...

Sheet Resumo
B1: Censo 2022
A2: Obrigados a elaborar o plano | B2: =COUNTIF(Levantamento!AH1:AH5572,"Sim") -> 1910
A3: Obrigados que prestaram informações | B3: =COUNTIFS(Levantamento!AH1:AH5572,"Sim",Levantamento!R1:R5572,"Sim") -> 1441 | C3: =B3/B2 -> 0.75445026
A4: Municípios que possuem plano | B4: =COUNTIF(Levantamento!S1:S5572,"Sim") -> 486
A5: Obrigados que possuem plano | B5: =COUNTIFS(Levantamento!AH1:AH5572,"Sim",Levantamento!S1:S5572,"Sim") -> 466 | C5: =B5/B2 -> 0.24397906
A6: Mais de 250 mil habitantes que possuem plano | B6: =COUNTIFS(Levantamento!N1:N5572,"Mais de 1 milhão", Levantamento!S1:S5572,"Sim")+COUNTIFS(Levantamento!N1:N5572,"De 500 mil a 1 milhão", Levantamento!S1:S5572,"Sim")+COUNTIFS(Levantamento!N1:N5572,"De 250 mil a 500 mil", Levantamento!S1:S5572,"Sim") -> 100 | C6: =B6/COUNTIF(Levantamento!M1:M5572,">=250000") -> 0.86206897
A7: Municípios com plano aprovado em instrumento normativo | B7: =COUNTIF(Levantamento!U1:U5572,"Sim") -> 407
A8: Obrigados com plano aprovado em instrumento normativo | B8: =COUNTIFS(Levantamento!AH1:AH5572,"Sim",Levantamento!U1:U5572,"Sim") -> 393 | C8: =B8/B2 -> 0.20575916
A9: Mais de 250 mil hab. com plano aprovado em instrumento normativo | B9: =COUNTIFS(Levantamento!N1:N5572,"Mais de 1 milhão", Levantamento!U1:U5572,"Sim")+COUNTIFS(Levantamento!N1:N5572,"De 500 mil a 1 milhão", Levantamento!U1:U5572,"Sim")+COUNTIFS(Levantamento!N1:N5572,"De 250 mil a 500 mil", Levantamento!U1:U5572,"Sim") -> 90 | C9: =B9/COUNTIF(Levantamento!M1:M5572,">=250000") -> 0.77586207
A11: N | E11: =COUNTIFS(Levantamento!$B$1:$B$5572,"N",Levantamento!$U$1:$U$5572,"Sim",Levantamento!$AI$1:$AI$5572,"Sim") -> 37 | F11: =COUNTIFS(Levantamento!$B$1:$B$5572,"N",Levantamento!$AI$1:$AI$5572,"Sim") -> 187 | H11: =E11/F11 -> 0.19786096
A12: NE | E12: =COUNTIFS(Levantamento!$B$1:$B$5572,"NE",Levantamento!$U$1:$U$5572,"Sim",Levantamento!$AI$1:$AI$5572,"Sim") -> 41 | F12: =COUNTIFS(Levantamento!$B$1:$B$5572,"NE",Levantamento!$AI$1:$AI$5572,"Sim") -> 623 | H12: =E12/F12 -> 0.065810594
A13: CO | E13: =COUNTIFS(Levantamento!$B$1:$B$5572,"CO",Levantamento!$U$1:$U$5572,"Sim",Levantamento!$AI$1:$AI$5572,"Sim") -> 26 | F13: =COUNTIFS(Levantamento!$B$1:$B$5572,"CO",Levantamento!$AI$1:$AI$5572,"Sim") -> 154 | H13: =E13/F13 -> 0.16883117
A14: SE | E14: =COUNTIFS(Levantamento!$B$1:$B$5572,"SE",Levantamento!$U$1:$U$5572,"Sim",Levantamento!$AI$1:$AI$5572,"Sim") -> 191 | F14: =COUNTIFS(Levantamento!$B$1:$B$5572,"SE",Levantamento!$AI$1:$AI$5572,"Sim") -> 613 | H14: =E14/F14 -> 0.31158238
A15: S | E15: =COUNTIFS(Levantamento!$B$1:$B$5572,"S",Levantamento!$U$1:$U$5572,"Sim",Levantamento!$AI$1:$AI$5572,"Sim") -> 98 | F15: =COUNTIFS(Levantamento!$B$1:$B$5572,"S",Levantamento!$AI$1:$AI$5572,"Sim") -> 333 | H15: =E15/F15 -> 0.29429429
B17: Estimativa 2025
A18: Obrigados a elaborar o plano | B18: =COUNTIF(Levantamento!AG1:AG5572,"Sim") -> 1979
A19: Obrigados que prestaram informações | B19: =COUNTIFS(Levantamento!AG1:AG5572,"Sim",Levantamento!R1:R5572,"Sim") -> 1464 | C19: =B19/B18 -> 0.73976756
A20: Municípios que possuem plano | B20: =COUNTIF(Levantamento!S1:S5572,"Sim") -> 486
A21: Obrigados que possuem plano | B21: =COUNTIFS(Levantamento!AG1:AG5572,"Sim",Levantamento!S1:S5572,"Sim") -> 468 | C21: =B21/B18 -> 0.23648307
A22: Mais de 250 mil habitantes que possuem plano | B22: =COUNTIFS(Levantamento!P1:P5572,"Mais de 1 milhão", Levantamento!S1:S5572,"Sim")+COUNTIFS(Levantamento!P1:P5572,"De 500 mil a 1 milhão", Levantamento!S1:S5572,"Sim")+COUNTIFS(Levantamento!P1:P5572,"De 250 mil a 500 mil", Levantamento!S1:S5572,"Sim") -> 103 | C22: =B22/COUNTIF(Levantamento!O1:O5572,">=250000") -> 0.824
A23: Municípios com plano aprovado em instrumento normativo | B23: =COUNTIF(Levantamento!U1:U5572,"Sim") -> 407
A24: Obrigados com plano aprovado em instrumento normativo | B24: =COUNTIFS(Levantamento!AG1:AG5572,"Sim",Levantamento!U1:U5572,"Sim") -> 394 | C24: =B24/B18 -> 0.19909045
A25: Mais de 250 mil hab. com plano aprovado em instrumento normativo | B25: =COUNTIFS(Levantamento!P1:P5572,"Mais de 1 milhão", Levantamento!U1:U5572,"Sim")+COUNTIFS(Levantamento!P1:P5572,"De 500 mil a 1 milhão", Levantamento!U1:U5572,"Sim")+COUNTIFS(Levantamento!P1:P5572,"De 250 mil a 500 mil", Levantamento!U1:U5572,"Sim") -> 92 | C25: =B25/COUNTIF(Levantamento!O1:O5572,">=250000") -> 0.736
